Workbook

Sheet admin-delete
B1: DELETE | C1: =API!$A$1 & "/devices/config/[DEV_ID]" &API!$A$2 -> http://localhost:8001/devices/config/[DEV_ID] | D1: delete [DEV_ID]'s config on DB
B2: Parameters
B3: Name | C3: Description
B4: DEV_ID | C4: ID of the tag
B5: Responses
B6: Code | C6: Description
B7: 2XX | C7: Success
C8: Model | D8: Example
C9: No model
B10: 4XX | C10: Error
B11: DELETE | C11: =API!$A$1 & "/asset/[ASSET_ID]"& API!$A$2 -> http://localhost:8001/asset/[ASSET_ID] | D11: delete [ASSET_ID] on DB
B12: Parameters
B13: Name | C13: Description
B14: ASSET_ID | C14: ID of the asset
B15: Responses
B16: Code | C16: Description
B17: 2XX | C17: Success
C18: Model | D18: Example
C19: No model
B20: 4XX | C20: Error

Sheet admin-get
A1: 3 | B1: GET | C1: =API!$A$1 & "/api/analyze/{analyze_id}"& API!$A$2 -> http://localhost:8001/api/analyze/{analyze_id} | D1: Retrieve a saved skin analysis result and its metadata from the database by its unique identifier.
B2: Parameters
B3: Name | C3: Description
B4: analyze_id
B5: Responses
B6: Code | C6: Description
B7: 200 | C7: Success
C8: Model | D8: Example
C9: { "id": "ana_xxxxxxxx (string)", "created_at": "ISO8601 timestamp", "tom_geral_fitzpatrick": 3, "tom_geral_hex": "#RRGGBB", "fitzpatrick_source": "claude", "subtom_predominante": "frio", "regioes": {}, "comparacao_tons": {}, "imperfeicoes": [], "recommendations": [], "skin_tone": {} } | D9: need details from Patrick
B10: 400 | C10: Not Found: Analysis result not found for the given ID.
B11: 500 | C11: Internal Server Error: Internal error while fetching the analysis from database.
A12: 4 | B12: GET | C12: =API!$A$1 & "/"& API!$A$2 -> http://localhost:8001/ | D12: Service health check and live monitoring of API status and Core Database connectivity.
B13: Parameters
B14: Name | C14: Description
B15: Responses
B16: Code | C16: Description
B17: 200 | C17: Success
C18: Model | D18: Example
C19: { "status": "ok", "service": "skin-analyzer", "db": "ok" }
B20: 400 | C20: Returns "db": "unreachable" if the database connection fails.
B21: GET | C21: =API!$A$1 & "/"& API!$A$2 -> http://localhost:8001/ | D21: Service health check and live monitoring of API status and Core Database connectivity.
B22: Parameters
B23: GROUP_ID | C23: ID of the group
B24: Name | C24: Description
B25: Responses
B26: Code | C26: Description
B27: 2XX | C27: Success
C28: Model | D28: Example
C29: [{ id: string, dev_id: string, name: string, type: string, x: 2 digit accurate number (not a required field, as only needed for anchors), y: 2 digit accurate number (not a required field, as only needed for anchors), z: 2 digit accurate number (not a required field, as only needed for anchors) },… ] | D29: [{ id: "1", dev_id: "9037", name: "SAAnchor2", type: "anchor", x: 20.00, y: 0.00, z: 2.00 },… ]
B30: 4XX | C30: Error
B31: GET | C31: =API!$A$1 & "/assets/anchors/[GROUP_ID]"& API!$A$2 -> http://localhost:8001/assets/anchors/[GROUP_ID] | D31: get details of all assets in [GROUP_ID], with type anchor, from DB
B32: Parameters
B33: Name | C33: Description
B34: GROUP_ID | C34: ID of the group
B35: Responses
B36: Code | C36: Description
B37: 2XX | C37: Success
C38: Model | D38: Example
C39: [{ id: string, dev_id: string, name: string, type: string, x: 2 digit accurate number (not a required field, as only needed for anchors), y: 2 digit accurate number (not a required field, as only needed for anchors), z: 2 digit accurate number (not a required field, as only needed for anchors) },… ] | D39: [{ id: "1", dev_id: "9037", name: "SAAnchor2", type: "anchor", x: 20.00, y: 0.00, z: 2.00 },… ]
B40: 4XX | C40: Error
...

Sheet admin-put
B1: PUT | C1: =API!$A$1 & "/devices/config/[DEV_ID]"& API!$A$2 -> http://localhost:8001/devices/config/[DEV_ID] | D1: push the config to [DEV_ID]
B2: FC_CONFIG => Listener
B3: Parameters
B4: Name | C4: Description
B5: DEV_ID | C5: ID of the tag
B6: Responses
B7: Code | C7: Description
B8: 2XX | C8: Success
C9: Model | D9: Example
C10: need details from Patrick | D10: need details from Patrick
B11: 4XX | C11: Error
B12: PUT | C12: =API!$A$1 & "/devices/status/[DEV_ID]"& API!$A$2 -> http://localhost:8001/devices/status/[DEV_ID] | D12: send status request to listener, for [DEV_ID], listener replies with a POST
B13: FC_STATUS_REQ => Listener
B14: Parameters
B15: Name | C15: Description
B16: DEV_ID | C16: ID of the tag
B17: Responses
B18: Code | C18: Description
B19: 2XX | C19: Success
C20: Model | D20: Example
C21: need details from Patrick | D21: need details from Patrick
B22: 4XX | C22: Error
B23: PUT | C23: =API!$A$1 & "/devices/restart/[DEV_ID]"& API!$A$2 -> http://localhost:8001/devices/restart/[DEV_ID] | D23: request reboot for [DEV_ID]
B24: FC_REBOOT => Listener
B25: Parameters
B26: Name | C26: Description
B27: DEV_ID | C27: ID of the tag
B28: Responses
B29: Code | C29: Description
B30: 2XX | C30: Success
C31: Model | D31: Example
C32: need details from Patrick | D32: need details from Patrick
B33: 4XX | C33: Error
B34: PUT | C34: =API!$A$1 & "/devices/gpio/[DEV_ID]/[MASK]"& API!$A$2 -> http://localhost:8001/devices/gpio/[DEV_ID]/[MASK] | D34: turn gpio (LEDs, or other I/O) on/off
B35: FC_GPIO => Listener
B36: Parameters
B37: Name | C37: Description
B38: DEV_ID | C38: ID of the tag
B39: MASK | C39: On/Off
B40: Responses
...

Sheet admin-post
A1: 6 | B1: POST | C1: =API!$A$1 & "/api/users/register"& API!$A$2 -> http://localhost:8001/api/users/register | D1: Create a new user account and profile in the system database, including required application-specific fields and initial user metadata.
B2: Parameters
B3: Name | C3: Description
B5: Responses
B6: Code | C6: Description
B7: 201 | C7: Created: Account created successfully and stored in the database.
C8: Model | D8: Example
C9: { "username": "string (required, unique)", "email": "string (required, valid email address)", "password": "string (required, hashed on backend)", "profile": { "first_name": "string", "last_name": "string", "age": "integer", "skin_type_self_assessed": "string (e.g., oily, dry, combination)" } } | D9: need details from Patrick
B10: 400 | C10: Bad Request: Username or email already exists, or missing required fields.
B11: 422 | C11: Unprocessable Entity: Invalid data format (e.g., poorly formatted email).
B12: 500 | C12: Internal Server Error: Internal database error during user creation.
B13: POST | C13: =API!$A$1 & "/asset/[ASSET_ID]"& API!$A$2 -> http://localhost:8001/asset/[ASSET_ID] | D13: create/update asset for [ASSET_ID] to DB
B14: Parameters
B15: Name | C15: Description
B16: ASSET_ID | C16: ID of the asset
B17: Responses
B18: Code | C18: Description
B19: 2XX | C19: Success
C20: Model | D20: Example
C21: need details from Patrick | D21: need details from Patrick
B22: 4XX | C22: Error

Sheet andon-get
A1: 5 | B1: GET | C1: =API!$A$1 & "/api/monitor/fallback-metrics"& API!$A$2 -> http://localhost:8001/api/monitor/fallback-metrics | D1: Monitor the execution source of the skin analyzer pipeline to detect model degradation (e.g., high ratio of 'claude' fallback over local 'bisenet').
B2: Parameters
B3: Name | C3: Description
B5: Responses
B6: Code | C6: Description
B7: 200 | C7: Metrics successfully calculated and retrieved.
C8: Model | D8: Example
C9: { "timestamp": "ISO8601 timestamp", "bisenet_success_rate": 0.95, "claude_fallback_count": 5, "status": "NORMAL" }
B10: 500 | C10: Internal Server Error: Failed to generate monitoring statistics.
B11: GET | C11: =API!$A$1 & "/tracking/points/[GROUP_ID]/"& API!$A$2 -> http://localhost:8001/tracking/points/[GROUP_ID]/ | D11: return an array of latest locations of all tags, for passed group
B12: Parameters
B13: Name | C13: Description
B14: GROUP_ID | C14: ID of the group
B15: Responses
B16: Code | C16: Description
B17: 2XX | C17: Success
C18: Model | D18: Example
C19: [{ "x": number, "y": number, "z": 3, "id": "string", "name": "string", "type": "string", "timestamp": "string" }, …] | D19: [{ "x": 1, "y": 2, "z": 3, "id": "9037", "name": "F2", "type": "AGV", "timestamp": "2019-01-09T18:55:17+00:00" }, …]
B20: 4XX | C20: Error
B21: GET | C21: =API!$A$1 & "/historic/point/[GROUP_ID]/[DEV_ID]/[START_DATETIME]/[END_DATETIME]"& API!$A$2 -> http://localhost:8001/historic/point/[GROUP_ID]/[DEV_ID]/[START_DATETIME]/[END_DATETIME] | D21: return an array of locations for passed tag, between 2 datetime values
B22: Parameters
B23: Name | C23: Description
B24: GROUP_ID | C24: ID of the group
B25: DEV_ID | C25: ID of the tag
B26: START_DATETIME | C26: Start datetime for datetime range | D26: YYYY-MM-DDTHH:MM:SS+00:00
B27: END_DATETIME | C27: End datetime for datetime range | D27: YYYY-MM-DDTHH:MM:SS+00:00
B28: Responses
B29: Code | C29: Description
B30: 2XX | C30: Success
C31: Model | D31: Example
C32: [{ "x": 2 decimal number, "y":2 decimal number, "z": 2 decimal number, "id": "string", "name": "string", "type": "string", "timestamp": "string" }, …] | D32: [{ "x": 1, "y": 2, "z": 3, "id": "9037", "name": "F2", "type": "AGV", "timestamp": "2019-01-09T18:55:17+00:00" }, …]
B33: 4XX | C33: Error
B34: GET | C34: =API!$A$1 & "/historic/points/[GROUP_ID]/[START_DATETIME]/[END_DATETIME]"& API!$A$2 -> http://localhost:8001/historic/points/[GROUP_ID]/[START_DATETIME]/[END_DATETIME] | D34: return an array of locations for all tags, in passed group, between 2 datetime values
B35: Parameters
B36: Name | C36: Description
B37: GROUP_ID | C37: ID of the group
B38: START_DATETIME | C38: Start datetime for datetime range | D38: YYYY-MM-DDTHH:MM:SS+00:00
B39: END_DATETIME | C39: End datetime for datetime range | D39: YYYY-MM-DDTHH:MM:SS+00:00
B40: Responses
B41: Code | C41: Description
...

Sheet listener-get
A1: 1 | B1: GET | C1: =API!$A$1 & "/"& API!$A$2 -> http://localhost:8001/ | D1: Service health check
B2: need to determine what service is to be used, before model can be determined does customer have an internal time sync? If so, how accurate?
B3: Parameters
B4: Name | C4: Description
B5: Responses
B6: Code | C6: Description
B7: 2XX | C7: Success
C8: Model | D8: Example
C9: { "status": "string", "service": "string" } | D9: { "status": "ok", "service": "skin-analyzer" }
B10: 4XX | C10: Error

Sheet listener-post
A1: 2 | B1: POST | C1: =API!$A$1 & "/api/analyze"& API!$A$2 -> http://localhost:8001/api/analyze | D1: Upload facial photos and perform skin analysis
B2: Parameters
B3: Name | C3: Description
B4: file | C4: UploadFile (multipart/form-data, support JPG/PNG/WebP，Max 10MB)
B5: Responses
B6: Code | C6: Description
B7: 200 | C7: Success
C8: Model | D8: Example
C9: { "tom_geral_fitzpatrick": "integer (1-6)", "tom_geral_hex": "string (#RRGGBB)", "fitzpatrick_source": "string (bisenet | claude)", "subtom_predominante": "string (quente | frio | neutro)", "regioes": { "testa/bochecha_e/nariz/queixo": { "tom_hex": "string", "tom_fitzpatrick": "integer", "subtom": "string", "oleosidade": "string", "imperfeicoes": "array [ { tipo: string, intensidade: string } ]", "uniformidade": "integer (0-10)", "notas": "string" } }, "comparacao_tons": { "region_vs_region": { "delta": "float", "nivel": "string (alto | moderado | baixo)" } }, "imperfeicoes": "array [ { tipo: string, intensidade: string, regiao: string } ]", "recommendations": "array [ { brand: string, shade_name: string, shade_code: string, undertone: string, shade_hex: string, price_range: string, where_to_buy: string } ]", "skin_tone": { "mean_rgb": "array [integer, integer, integer] | null", "mean_hex": "string | null", "median_rgb": "array [integer, integer, integer] | null", "median_hex": "string | null", "num_skin_pixels": "integer" } } | D9: { "tom_geral_fitzpatrick": 3, "tom_geral_hex": "#d4a574", "fitzpatrick_source": "bisenet", "subtom_predominante": "neutro", "regioes": { "testa": { "tom_hex": "#d0a070", "tom_fitzpatrick": 3, "subtom": "quente", "oleosidade": "normal", "imperfeicoes": [ {"tipo": "poro", "intensidade": "moderado"} ], "uniformidade": 7, "notas": "Slightly warmer than average; open pores." } }, "comparacao_tons": { "testa_vs_bochecha_e": { "delta": 12.34, "nivel": "moderado" } }, "imperfeicoes": [ {"tipo": "poro", "intensidade": "moderado", "regiao": "testa"} ], "recommendations": [ { "brand": "Fenty Beauty", "shade_name": "330N", "shade_code": "330N", "undertone": "neutro", "shade_hex": "#c9976f", "price_range": "$38–$42", "where_to_buy": "https://www.fentybeauty.com" } ], "skin_tone": { "mean_rgb": [212, 165, 116], "mean_hex": "#d4a574", "median_rgb": [215, 168, 119], "median_hex": "#d7a877", "num_skin_pixels": 45000 } }
B10: 400 | C10: Invalid format. Use JPG, PNG or WebP.
C11: Model | D11: Example
C12: { "detail": "string" } | D12: { "detail": "Invalid format. Use JPG, PNG or WebP." }
B13: 413 | C13: Image too large. Maximum 10MB.
C14: Model | D14: Example
C15: { "detail": "string" } | D15: { "detail": "Image too large. Maximum 10MB." }
B16: 422 | C16: Validation fail (ValueError inside pipeline)
C17: Model | D17: Example
C18: { "detail": "string" } | D18: { "detail": "No face detected in the uploaded image." }
B19: 500 | C19: Internal error while analyzing the image.
C20: Model | D20: Example
C21: { "detail": "string" } | D21: { "detail": "Internal error while analyzing the image." }
B22: POST | C22: =API!$A$1 & "/devices/status/[DEV_ID]"& API!$A$2 -> http://localhost:8001/devices/status/[DEV_ID] | D22: status of [DEV_ID]
B23: Parameters
B24: Name | C24: Description
B25: DEV_ID | C25: ID of the tag
B26: Responses
B27: Code | C27: Description
B28: 2XX | C28: Success
C29: Model | D29: Example
C30: need details from Patrick | D30: need details from Patrick
B31: 4XX | C31: Error
B32: POST | C32: =API!$A$1 & "/devices/rt/[DEV_ID]"& API!$A$2 -> http://localhost:8001/devices/rt/[DEV_ID] | D32: DEV_ID routing table contents
B33: Parameters
B34: Name | C34: Description
B35: DEV_ID | C35: ID of the tag
B36: Responses
B37: Code | C37: Description
B38: 2XX | C38: Success
C39: Model | D39: Example
C40: need details from Patrick | D40: need details from Patrick
...

Sheet API
A1: http://localhost:8001 | B1: <--Base URL
B2: <--N/A | C2: ?apikey=#####
A4: Priority List
A5: 1 | B5: =IFERROR(VLOOKUP($A5,'listener-get'!$A:$D,2,FALSE),IFERROR(VLOOKUP($A5,'listener-post'!$A:$D,2,FALSE),IFERROR(VLOOKUP($A5,'andon-get'!$A:$D,2,FALSE),IFERROR(VLOOKUP($A5,'admin-delete'!$A:$D,2,FALSE),IFERROR(VLOOKUP($A5,'admin-get'!$A:$D,2,FALSE),IFERROR(VLOOKUP($A5,'admin-put'!$A:$D,2,FALSE),IFERROR(VLOOKUP($A5,'admin-post'!$A:$D,2,FALSE),""))))))) -> GET | C5: =IFERROR(VLOOKUP($A5,'listener-get'!$A:$D,3,FALSE),IFERROR(VLOOKUP($A5,'listener-post'!$A:$D,3,FALSE),IFERROR(VLOOKUP($A5,'andon-get'!$A:$D,3,FALSE),IFERROR(VLOOKUP($A5,'admin-delete'!$A:$D,3,FALSE),IFERROR(VLOOKUP($A5,'admin-get'!$A:$D,3,FALSE),IFERROR(VLOOKUP($A5,'admin-put'!$A:$D,3,FALSE),IFERROR(VLOOKUP($A5,'admin-post'!$A:$D,3,FALSE),""))))))) -> http://localhost:8001/ | D5: =IF(IFERROR(MATCH(A5,'listener-get'!$A:$A,0),"")<>"","listener-get",IF(IFERROR(MATCH(A5,'listener-post'!$A:$A,0),"")<>"","listener-post",IF(IFERROR(MATCH(A5,'andon-get'!$A:$A,0),"")<>"","andon-get",IF(IFERROR(MATCH(A5,'admin-post'!$A:$A,0),"")<>"","admin-post",IF(IFERROR(MATCH(A5,'admin-put'!$A:$A,0),"")<>"","admin-put",IF(IFERROR(MATCH(A5,'admin-get'!$A:$A,0),"")<>"","admin-get",IF(IFERROR(MATCH(A5,'admin-delete'!$A:$A,0),"")<>"","admin-delete",""))))))) -> listener-get
A6: 2 | B6: =IFERROR(VLOOKUP($A6,'listener-get'!$A:$D,2,FALSE),IFERROR(VLOOKUP($A6,'listener-post'!$A:$D,2,FALSE),IFERROR(VLOOKUP($A6,'andon-get'!$A:$D,2,FALSE),IFERROR(VLOOKUP($A6,'admin-delete'!$A:$D,2,FALSE),IFERROR(VLOOKUP($A6,'admin-get'!$A:$D,2,FALSE),IFERROR(VLOOKUP($A6,'admin-put'!$A:$D,2,FALSE),IFERROR(VLOOKUP($A6,'admin-post'!$A:$D,2,FALSE),""))))))) -> POST | C6: =IFERROR(VLOOKUP($A6,'listener-get'!$A:$D,3,FALSE),IFERROR(VLOOKUP($A6,'listener-post'!$A:$D,3,FALSE),IFERROR(VLOOKUP($A6,'andon-get'!$A:$D,3,FALSE),IFERROR(VLOOKUP($A6,'admin-delete'!$A:$D,3,FALSE),IFERROR(VLOOKUP($A6,'admin-get'!$A:$D,3,FALSE),IFERROR(VLOOKUP($A6,'admin-put'!$A:$D,3,FALSE),IFERROR(VLOOKUP($A6,'admin-post'!$A:$D,3,FALSE),""))))))) -> http://localhost:8001/api/analyze | D6: =IF(IFERROR(MATCH(A6,'listener-get'!$A:$A,0),"")<>"","listener-get",IF(IFERROR(MATCH(A6,'listener-post'!$A:$A,0),"")<>"","listener-post",IF(IFERROR(MATCH(A6,'andon-get'!$A:$A,0),"")<>"","andon-get",IF(IFERROR(MATCH(A6,'admin-post'!$A:$A,0),"")<>"","admin-post",IF(IFERROR(MATCH(A6,'admin-put'!$A:$A,0),"")<>"","admin-put",IF(IFERROR(MATCH(A6,'admin-get'!$A:$A,0),"")<>"","admin-get",IF(IFERROR(MATCH(A6,'admin-delete'!$A:$A,0),"")<>"","admin-delete",""))))))) -> listener-post
A7: 3 | B7: =IFERROR(VLOOKUP($A7,'listener-get'!$A:$D,2,FALSE),IFERROR(VLOOKUP($A7,'listener-post'!$A:$D,2,FALSE),IFERROR(VLOOKUP($A7,'andon-get'!$A:$D,2,FALSE),IFERROR(VLOOKUP($A7,'admin-delete'!$A:$D,2,FALSE),IFERROR(VLOOKUP($A7,'admin-get'!$A:$D,2,FALSE),IFERROR(VLOOKUP($A7,'admin-put'!$A:$D,2,FALSE),IFERROR(VLOOKUP($A7,'admin-post'!$A:$D,2,FALSE),""))))))) -> GET | C7: =IFERROR(VLOOKUP($A7,'listener-get'!$A:$D,3,FALSE),IFERROR(VLOOKUP($A7,'listener-post'!$A:$D,3,FALSE),IFERROR(VLOOKUP($A7,'andon-get'!$A:$D,3,FALSE),IFERROR(VLOOKUP($A7,'admin-delete'!$A:$D,3,FALSE),IFERROR(VLOOKUP($A7,'admin-get'!$A:$D,3,FALSE),IFERROR(VLOOKUP($A7,'admin-put'!$A:$D,3,FALSE),IFERROR(VLOOKUP($A7,'admin-post'!$A:$D,3,FALSE),""))))))) -> http://localhost:8001/api/analyze/{analyze_id} | D7: =IF(IFERROR(MATCH(A7,'listener-get'!$A:$A,0),"")<>"","listener-get",IF(IFERROR(MATCH(A7,'listener-post'!$A:$A,0),"")<>"","listener-post",IF(IFERROR(MATCH(A7,'andon-get'!$A:$A,0),"")<>"","andon-get",IF(IFERROR(MATCH(A7,'admin-post'!$A:$A,0),"")<>"","admin-post",IF(IFERROR(MATCH(A7,'admin-put'!$A:$A,0),"")<>"","admin-put",IF(IFERROR(MATCH(A7,'admin-get'!$A:$A,0),"")<>"","admin-get",IF(IFERROR(MATCH(A7,'admin-delete'!$A:$A,0),"")<>"","admin-delete",""))))))) -> admin-get
A8: 4 | B8: =IFERROR(VLOOKUP($A8,'listener-get'!$A:$D,2,FALSE),IFERROR(VLOOKUP($A8,'listener-post'!$A:$D,2,FALSE),IFERROR(VLOOKUP($A8,'andon-get'!$A:$D,2,FALSE),IFERROR(VLOOKUP($A8,'admin-delete'!$A:$D,2,FALSE),IFERROR(VLOOKUP($A8,'admin-get'!$A:$D,2,FALSE),IFERROR(VLOOKUP($A8,'admin-put'!$A:$D,2,FALSE),IFERROR(VLOOKUP($A8,'admin-post'!$A:$D,2,FALSE),""))))))) -> GET | C8: =IFERROR(VLOOKUP($A8,'listener-get'!$A:$D,3,FALSE),IFERROR(VLOOKUP($A8,'listener-post'!$A:$D,3,FALSE),IFERROR(VLOOKUP($A8,'andon-get'!$A:$D,3,FALSE),IFERROR(VLOOKUP($A8,'admin-delete'!$A:$D,3,FALSE),IFERROR(VLOOKUP($A8,'admin-get'!$A:$D,3,FALSE),IFERROR(VLOOKUP($A8,'admin-put'!$A:$D,3,FALSE),IFERROR(VLOOKUP($A8,'admin-post'!$A:$D,3,FALSE),""))))))) -> http://localhost:8001/ | D8: =IF(IFERROR(MATCH(A8,'listener-get'!$A:$A,0),"")<>"","listener-get",IF(IFERROR(MATCH(A8,'listener-post'!$A:$A,0),"")<>"","listener-post",IF(IFERROR(MATCH(A8,'andon-get'!$A:$A,0),"")<>"","andon-get",IF(IFERROR(MATCH(A8,'admin-post'!$A:$A,0),"")<>"","admin-post",IF(IFERROR(MATCH(A8,'admin-put'!$A:$A,0),"")<>"","admin-put",IF(IFERROR(MATCH(A8,'admin-get'!$A:$A,0),"")<>"","admin-get",IF(IFERROR(MATCH(A8,'admin-delete'!$A:$A,0),"")<>"","admin-delete",""))))))) -> admin-get
A9: 5 | B9: =IFERROR(VLOOKUP($A9,'listener-get'!$A:$D,2,FALSE),IFERROR(VLOOKUP($A9,'listener-post'!$A:$D,2,FALSE),IFERROR(VLOOKUP($A9,'andon-get'!$A:$D,2,FALSE),IFERROR(VLOOKUP($A9,'admin-delete'!$A:$D,2,FALSE),IFERROR(VLOOKUP($A9,'admin-get'!$A:$D,2,FALSE),IFERROR(VLOOKUP($A9,'admin-put'!$A:$D,2,FALSE),IFERROR(VLOOKUP($A9,'admin-post'!$A:$D,2,FALSE),""))))))) -> GET | C9: =IFERROR(VLOOKUP($A9,'listener-get'!$A:$D,3,FALSE),IFERROR(VLOOKUP($A9,'listener-post'!$A:$D,3,FALSE),IFERROR(VLOOKUP($A9,'andon-get'!$A:$D,3,FALSE),IFERROR(VLOOKUP($A9,'admin-delete'!$A:$D,3,FALSE),IFERROR(VLOOKUP($A9,'admin-get'!$A:$D,3,FALSE),IFERROR(VLOOKUP($A9,'admin-put'!$A:$D,3,FALSE),IFERROR(VLOOKUP($A9,'admin-post'!$A:$D,3,FALSE),""))))))) -> http://localhost:8001/api/monitor/fallback-metrics | D9: =IF(IFERROR(MATCH(A9,'listener-get'!$A:$A,0),"")<>"","listener-get",IF(IFERROR(MATCH(A9,'listener-post'!$A:$A,0),"")<>"","listener-post",IF(IFERROR(MATCH(A9,'andon-get'!$A:$A,0),"")<>"","andon-get",IF(IFERROR(MATCH(A9,'admin-post'!$A:$A,0),"")<>"","admin-post",IF(IFERROR(MATCH(A9,'admin-put'!$A:$A,0),"")<>"","admin-put",IF(IFERROR(MATCH(A9,'admin-get'!$A:$A,0),"")<>"","admin-get",IF(IFERROR(MATCH(A9,'admin-delete'!$A:$A,0),"")<>"","admin-delete",""))))))) -> andon-get
A10: 6 | B10: =IFERROR(VLOOKUP($A10,'listener-get'!$A:$D,2,FALSE),IFERROR(VLOOKUP($A10,'listener-post'!$A:$D,2,FALSE),IFERROR(VLOOKUP($A10,'andon-get'!$A:$D,2,FALSE),IFERROR(VLOOKUP($A10,'admin-delete'!$A:$D,2,FALSE),IFERROR(VLOOKUP($A10,'admin-get'!$A:$D,2,FALSE),IFERROR(VLOOKUP($A10,'admin-put'!$A:$D,2,FALSE),IFERROR(VLOOKUP($A10,'admin-post'!$A:$D,2,FALSE),""))))))) -> POST | C10: =IFERROR(VLOOKUP($A10,'listener-get'!$A:$D,3,FALSE),IFERROR(VLOOKUP($A10,'listener-post'!$A:$D,3,FALSE),IFERROR(VLOOKUP($A10,'andon-get'!$A:$D,3,FALSE),IFERROR(VLOOKUP($A10,'admin-delete'!$A:$D,3,FALSE),IFERROR(VLOOKUP($A10,'admin-get'!$A:$D,3,FALSE),IFERROR(VLOOKUP($A10,'admin-put'!$A:$D,3,FALSE),IFERROR(VLOOKUP($A10,'admin-post'!$A:$D,3,FALSE),""))))))) -> http://localhost:8001/api/users/register | D10: =IF(IFERROR(MATCH(A10,'listener-get'!$A:$A,0),"")<>"","listener-get",IF(IFERROR(MATCH(A10,'listener-post'!$A:$A,0),"")<>"","listener-post",IF(IFERROR(MATCH(A10,'andon-get'!$A:$A,0),"")<>"","andon-get",IF(IFERROR(MATCH(A10,'admin-post'!$A:$A,0),"")<>"","admin-post",IF(IFERROR(MATCH(A10,'admin-put'!$A:$A,0),"")<>"","admin-put",IF(IFERROR(MATCH(A10,'admin-get'!$A:$A,0),"")<>"","admin-get",IF(IFERROR(MATCH(A10,'admin-delete'!$A:$A,0),"")<>"","admin-delete",""))))))) -> admin-post
A11: 7 | B11: =IFERROR(VLOOKUP($A11,'listener-get'!$A:$D,2,FALSE),IFERROR(VLOOKUP($A11,'listener-post'!$A:$D,2,FALSE),IFERROR(VLOOKUP($A11,'andon-get'!$A:$D,2,FALSE),IFERROR(VLOOKUP($A11,'admin-delete'!$A:$D,2,FALSE),IFERROR(VLOOKUP($A11,'admin-get'!$A:$D,2,FALSE),IFERROR(VLOOKUP($A11,'admin-put'!$A:$D,2,FALSE),IFERROR(VLOOKUP($A11,'admin-post'!$A:$D,2,FALSE),""))))))) | C11: =IFERROR(VLOOKUP($A11,'listener-get'!$A:$D,3,FALSE),IFERROR(VLOOKUP($A11,'listener-post'!$A:$D,3,FALSE),IFERROR(VLOOKUP($A11,'andon-get'!$A:$D,3,FALSE),IFERROR(VLOOKUP($A11,'admin-delete'!$A:$D,3,FALSE),IFERROR(VLOOKUP($A11,'admin-get'!$A:$D,3,FALSE),IFERROR(VLOOKUP($A11,'admin-put'!$A:$D,3,FALSE),IFERROR(VLOOKUP($A11,'admin-post'!$A:$D,3,FALSE),""))))))) | D11: =IF(IFERROR(MATCH(A11,'listener-get'!$A:$A,0),"")<>"","listener-get",IF(IFERROR(MATCH(A11,'listener-post'!$A:$A,0),"")<>"","listener-post",IF(IFERROR(MATCH(A11,'andon-get'!$A:$A,0),"")<>"","andon-get",IF(IFERROR(MATCH(A11,'admin-post'!$A:$A,0),"")<>"","admin-post",IF(IFERROR(MATCH(A11,'admin-put'!$A:$A,0),"")<>"","admin-put",IF(IFERROR(MATCH(A11,'admin-get'!$A:$A,0),"")<>"","admin-get",IF(IFERROR(MATCH(A11,'admin-delete'!$A:$A,0),"")<>"","admin-delete","")))))))
A12: 8 | B12: =IFERROR(VLOOKUP($A12,'listener-get'!$A:$D,2,FALSE),IFERROR(VLOOKUP($A12,'listener-post'!$A:$D,2,FALSE),IFERROR(VLOOKUP($A12,'andon-get'!$A:$D,2,FALSE),IFERROR(VLOOKUP($A12,'admin-delete'!$A:$D,2,FALSE),IFERROR(VLOOKUP($A12,'admin-get'!$A:$D,2,FALSE),IFERROR(VLOOKUP($A12,'admin-put'!$A:$D,2,FALSE),IFERROR(VLOOKUP($A12,'admin-post'!$A:$D,2,FALSE),""))))))) | C12: =IFERROR(VLOOKUP($A12,'listener-get'!$A:$D,3,FALSE),IFERROR(VLOOKUP($A12,'listener-post'!$A:$D,3,FALSE),IFERROR(VLOOKUP($A12,'andon-get'!$A:$D,3,FALSE),IFERROR(VLOOKUP($A12,'admin-delete'!$A:$D,3,FALSE),IFERROR(VLOOKUP($A12,'admin-get'!$A:$D,3,FALSE),IFERROR(VLOOKUP($A12,'admin-put'!$A:$D,3,FALSE),IFERROR(VLOOKUP($A12,'admin-post'!$A:$D,3,FALSE),""))))))) | D12: =IF(IFERROR(MATCH(A12,'listener-get'!$A:$A,0),"")<>"","listener-get",IF(IFERROR(MATCH(A12,'listener-post'!$A:$A,0),"")<>"","listener-post",IF(IFERROR(MATCH(A12,'andon-get'!$A:$A,0),"")<>"","andon-get",IF(IFERROR(MATCH(A12,'admin-post'!$A:$A,0),"")<>"","admin-post",IF(IFERROR(MATCH(A12,'admin-put'!$A:$A,0),"")<>"","admin-put",IF(IFERROR(MATCH(A12,'admin-get'!$A:$A,0),"")<>"","admin-get",IF(IFERROR(MATCH(A12,'admin-delete'!$A:$A,0),"")<>"","admin-delete","")))))))
A13: 9 | B13: =IFERROR(VLOOKUP($A13,'listener-get'!$A:$D,2,FALSE),IFERROR(VLOOKUP($A13,'listener-post'!$A:$D,2,FALSE),IFERROR(VLOOKUP($A13,'andon-get'!$A:$D,2,FALSE),IFERROR(VLOOKUP($A13,'admin-delete'!$A:$D,2,FALSE),IFERROR(VLOOKUP($A13,'admin-get'!$A:$D,2,FALSE),IFERROR(VLOOKUP($A13,'admin-put'!$A:$D,2,FALSE),IFERROR(VLOOKUP($A13,'admin-post'!$A:$D,2,FALSE),""))))))) | C13: =IFERROR(VLOOKUP($A13,'listener-get'!$A:$D,3,FALSE),IFERROR(VLOOKUP($A13,'listener-post'!$A:$D,3,FALSE),IFERROR(VLOOKUP($A13,'andon-get'!$A:$D,3,FALSE),IFERROR(VLOOKUP($A13,'admin-delete'!$A:$D,3,FALSE),IFERROR(VLOOKUP($A13,'admin-get'!$A:$D,3,FALSE),IFERROR(VLOOKUP($A13,'admin-put'!$A:$D,3,FALSE),IFERROR(VLOOKUP($A13,'admin-post'!$A:$D,3,FALSE),""))))))) | D13: =IF(IFERROR(MATCH(A13,'listener-get'!$A:$A,0),"")<>"","listener-get",IF(IFERROR(MATCH(A13,'listener-post'!$A:$A,0),"")<>"","listener-post",IF(IFERROR(MATCH(A13,'andon-get'!$A:$A,0),"")<>"","andon-get",IF(IFERROR(MATCH(A13,'admin-post'!$A:$A,0),"")<>"","admin-post",IF(IFERROR(MATCH(A13,'admin-put'!$A:$A,0),"")<>"","admin-put",IF(IFERROR(MATCH(A13,'admin-get'!$A:$A,0),"")<>"","admin-get",IF(IFERROR(MATCH(A13,'admin-delete'!$A:$A,0),"")<>"","admin-delete","")))))))
A14: 10 | B14: =IFERROR(VLOOKUP($A14,'listener-get'!$A:$D,2,FALSE),IFERROR(VLOOKUP($A14,'listener-post'!$A:$D,2,FALSE),IFERROR(VLOOKUP($A14,'andon-get'!$A:$D,2,FALSE),IFERROR(VLOOKUP($A14,'admin-delete'!$A:$D,2,FALSE),IFERROR(VLOOKUP($A14,'admin-get'!$A:$D,2,FALSE),IFERROR(VLOOKUP($A14,'admin-put'!$A:$D,2,FALSE),IFERROR(VLOOKUP($A14,'admin-post'!$A:$D,2,FALSE),""))))))) | C14: =IFERROR(VLOOKUP($A14,'listener-get'!$A:$D,3,FALSE),IFERROR(VLOOKUP($A14,'listener-post'!$A:$D,3,FALSE),IFERROR(VLOOKUP($A14,'andon-get'!$A:$D,3,FALSE),IFERROR(VLOOKUP($A14,'admin-delete'!$A:$D,3,FALSE),IFERROR(VLOOKUP($A14,'admin-get'!$A:$D,3,FALSE),IFERROR(VLOOKUP($A14,'admin-put'!$A:$D,3,FALSE),IFERROR(VLOOKUP($A14,'admin-post'!$A:$D,3,FALSE),""))))))) | D14: =IF(IFERROR(MATCH(A14,'listener-get'!$A:$A,0),"")<>"","listener-get",IF(IFERROR(MATCH(A14,'listener-post'!$A:$A,0),"")<>"","listener-post",IF(IFERROR(MATCH(A14,'andon-get'!$A:$A,0),"")<>"","andon-get",IF(IFERROR(MATCH(A14,'admin-post'!$A:$A,0),"")<>"","admin-post",IF(IFERROR(MATCH(A14,'admin-put'!$A:$A,0),"")<>"","admin-put",IF(IFERROR(MATCH(A14,'admin-get'!$A:$A,0),"")<>"","admin-get",IF(IFERROR(MATCH(A14,'admin-delete'!$A:$A,0),"")<>"","admin-delete","")))))))
A15: 11 | B15: =IFERROR(VLOOKUP($A15,'listener-get'!$A:$D,2,FALSE),IFERROR(VLOOKUP($A15,'listener-post'!$A:$D,2,FALSE),IFERROR(VLOOKUP($A15,'andon-get'!$A:$D,2,FALSE),IFERROR(VLOOKUP($A15,'admin-delete'!$A:$D,2,FALSE),IFERROR(VLOOKUP($A15,'admin-get'!$A:$D,2,FALSE),IFERROR(VLOOKUP($A15,'admin-put'!$A:$D,2,FALSE),IFERROR(VLOOKUP($A15,'admin-post'!$A:$D,2,FALSE),""))))))) | C15: =IFERROR(VLOOKUP($A15,'listener-get'!$A:$D,3,FALSE),IFERROR(VLOOKUP($A15,'listener-post'!$A:$D,3,FALSE),IFERROR(VLOOKUP($A15,'andon-get'!$A:$D,3,FALSE),IFERROR(VLOOKUP($A15,'admin-delete'!$A:$D,3,FALSE),IFERROR(VLOOKUP($A15,'admin-get'!$A:$D,3,FALSE),IFERROR(VLOOKUP($A15,'admin-put'!$A:$D,3,FALSE),IFERROR(VLOOKUP($A15,'admin-post'!$A:$D,3,FALSE),""))))))) | D15: =IF(IFERROR(MATCH(A15,'listener-get'!$A:$A,0),"")<>"","listener-get",IF(IFERROR(MATCH(A15,'listener-post'!$A:$A,0),"")<>"","listener-post",IF(IFERROR(MATCH(A15,'andon-get'!$A:$A,0),"")<>"","andon-get",IF(IFERROR(MATCH(A15,'admin-post'!$A:$A,0),"")<>"","admin-post",IF(IFERROR(MATCH(A15,'admin-put'!$A:$A,0),"")<>"","admin-put",IF(IFERROR(MATCH(A15,'admin-get'!$A:$A,0),"")<>"","admin-get",IF(IFERROR(MATCH(A15,'admin-delete'!$A:$A,0),"")<>"","admin-delete","")))))))
A16: 12 | B16: =IFERROR(VLOOKUP($A16,'listener-get'!$A:$D,2,FALSE),IFERROR(VLOOKUP($A16,'listener-post'!$A:$D,2,FALSE),IFERROR(VLOOKUP($A16,'andon-get'!$A:$D,2,FALSE),IFERROR(VLOOKUP($A16,'admin-delete'!$A:$D,2,FALSE),IFERROR(VLOOKUP($A16,'admin-get'!$A:$D,2,FALSE),IFERROR(VLOOKUP($A16,'admin-put'!$A:$D,2,FALSE),IFERROR(VLOOKUP($A16,'admin-post'!$A:$D,2,FALSE),""))))))) | C16: =IFERROR(VLOOKUP($A16,'listener-get'!$A:$D,3,FALSE),IFERROR(VLOOKUP($A16,'listener-post'!$A:$D,3,FALSE),IFERROR(VLOOKUP($A16,'andon-get'!$A:$D,3,FALSE),IFERROR(VLOOKUP($A16,'admin-delete'!$A:$D,3,FALSE),IFERROR(VLOOKUP($A16,'admin-get'!$A:$D,3,FALSE),IFERROR(VLOOKUP($A16,'admin-put'!$A:$D,3,FALSE),IFERROR(VLOOKUP($A16,'admin-post'!$A:$D,3,FALSE),""))))))) | D16: =IF(IFERROR(MATCH(A16,'listener-get'!$A:$A,0),"")<>"","listener-get",IF(IFERROR(MATCH(A16,'listener-post'!$A:$A,0),"")<>"","listener-post",IF(IFERROR(MATCH(A16,'andon-get'!$A:$A,0),"")<>"","andon-get",IF(IFERROR(MATCH(A16,'admin-post'!$A:$A,0),"")<>"","admin-post",IF(IFERROR(MATCH(A16,'admin-put'!$A:$A,0),"")<>"","admin-put",IF(IFERROR(MATCH(A16,'admin-get'!$A:$A,0),"")<>"","admin-get",IF(IFERROR(MATCH(A16,'admin-delete'!$A:$A,0),"")<>"","admin-delete","")))))))
... A24: 20 | B24: =IFERROR(VLOOKUP($A24,'listener-get'!$A:$D,2,FALSE),IFERROR(VLOOKUP($A24,'listener-post'!$A:$D,2,FALSE),IFERROR(VLOOKUP($A24,'andon-get'!$A:$D,2,FALSE),IFERROR(VLOOKUP($A24,'admin-delete'!$A:$D,2,FALSE),IFERROR(VLOOKUP($A24,'admin-get'!$A:$D,2,FALSE),IFERROR(VLOOKUP($A24,'admin-put'!$A:$D,2,FALSE),IFERROR(VLOOKUP($A24,'admin-post'!$A:$D,2,FALSE),""))))))) | C24: =IFERROR(VLOOKUP($A24,'listener-get'!$A:$D,3,FALSE),IFERROR(VLOOKUP($A24,'listener-post'!$A:$D,3,FALSE),IFERROR(VLOOKUP($A24,'andon-get'!$A:$D,3,FALSE),IFERROR(VLOOKUP($A24,'admin-delete'!$A:$D,3,FALSE),IFERROR(VLOOKUP($A24,'admin-get'!$A:$D,3,FALSE),IFERROR(VLOOKUP($A24,'admin-put'!$A:$D,3,FALSE),IFERROR(VLOOKUP($A24,'admin-post'!$A:$D,3,FALSE),""))))))) | D24: =IF(IFERROR(MATCH(A24,'listener-get'!$A:$A,0),"")<>"","listener-get",IF(IFERROR(MATCH(A24,'listener-post'!$A:$A,0),"")<>"","listener-post",IF(IFERROR(MATCH(A24,'andon-get'!$A:$A,0),"")<>"","andon-get",IF(IFERROR(MATCH(A24,'admin-post'!$A:$A,0),"")<>"","admin-post",IF(IFERROR(MATCH(A24,'admin-put'!$A:$A,0),"")<>"","admin-put",IF(IFERROR(MATCH(A24,'admin-get'!$A:$A,0),"")<>"","admin-get",IF(IFERROR(MATCH(A24,'admin-delete'!$A:$A,0),"")<>"","admin-delete","")))))))

Sheet help
B1: End Point | C1: Method | D1: Params | E1: Body | F1: Result | G1: Send to listener
B2: ../sw/images/[SW_VER]/[BLOCK_ID] | C2: GET | E2: BLOCK_SIZE chunk of s/w IMG SW_VER indexed by BLOCK_ID | F2: Return a chunk (BLOCK_ID) from software img SW_VER to requestor | G2: N/A
B4: process still TBD
